
PLAY [asa] *********************************************************************

TASK [Backup to tftp] **********************************************************
An exception occurred during task execution. To see the full traceback, use -vvv. The error was: FW-INET#
fatal: [192.168.201.18]: FAILED! => {"ansible_facts": {"discovered_interpreter_python": "/usr/libexec/platform-python"}, "changed": false, "module_stderr": "Traceback (most recent call last):\n  File \"/home/alex/.ansible/tmp/ansible-local-30447lh8varvg/ansible-tmp-1587495003.161476-200814690804865/AnsiballZ_asa_command.py\", line 102, in <module>\n    _ansiballz_main()\n  File \"/home/alex/.ansible/tmp/ansible-local-30447lh8varvg/ansible-tmp-1587495003.161476-200814690804865/AnsiballZ_asa_command.py\", line 94, in _ansiballz_main\n    invoke_module(zipped_mod, temp_path, ANSIBALLZ_PARAMS)\n  File \"/home/alex/.ansible/tmp/ansible-local-30447lh8varvg/ansible-tmp-1587495003.161476-200814690804865/AnsiballZ_asa_command.py\", line 40, in invoke_module\n    runpy.run_module(mod_name='ansible.modules.network.asa.asa_command', init_globals=None, run_name='__main__', alter_sys=True)\n  File \"/usr/lib64/python3.6/runpy.py\", line 205, in run_module\n    return _run_module_code(code, init_globals, run_name, mod_spec)\n  File \"/usr/lib64/python3.6/runpy.py\", line 96, in _run_module_code\n    mod_name, mod_spec, pkg_name, script_name)\n  File \"/usr/lib64/python3.6/runpy.py\", line 85, in _run_code\n    exec(code, run_globals)\n  File \"/tmp/ansible_asa_command_payload_r1xwz2k7/ansible_asa_command_payload.zip/ansible/modules/network/asa/asa_command.py\", line 186, in <module>\n  File \"/tmp/ansible_asa_command_payload_r1xwz2k7/ansible_asa_command_payload.zip/ansible/modules/network/asa/asa_command.py\", line 156, in main\n  File \"/tmp/ansible_asa_command_payload_r1xwz2k7/ansible_asa_command_payload.zip/ansible/module_utils/network/asa/asa.py\", line 125, in run_commands\n  File \"/tmp/ansible_asa_command_payload_r1xwz2k7/ansible_asa_command_payload.zip/ansible/module_utils/connection.py\", line 185, in __rpc__\nansible.module_utils.connection.ConnectionError: .. Done!\r\nCopying Backup ...!\r\n%Error writing tftp://10.1.0.84/fw-inet-wan//FW-INET.backup.2020-04-22-005004.tar.gz (Timed out attempting to connect)ERROR: Resource temporarily unavailable\r\n Failed!\r\nCleaning up ... Done!\r\nERROR: Backup failed!\r\n\rFW-INET# \n", "module_stdout": "", "msg": "MODULE FAILURE\nSee stdout/stderr for the exact error", "rc": 1}
An exception occurred during task execution. To see the full traceback, use -vvv. The error was: FW-WAN#
fatal: [192.168.201.10]: FAILED! => {"ansible_facts": {"discovered_interpreter_python": "/usr/libexec/platform-python"}, "changed": false, "module_stderr": "Traceback (most recent call last):\n  File \"/home/alex/.ansible/tmp/ansible-local-30447lh8varvg/ansible-tmp-1587495003.1817515-125465728235717/AnsiballZ_asa_command.py\", line 102, in <module>\n    _ansiballz_main()\n  File \"/home/alex/.ansible/tmp/ansible-local-30447lh8varvg/ansible-tmp-1587495003.1817515-125465728235717/AnsiballZ_asa_command.py\", line 94, in _ansiballz_main\n    invoke_module(zipped_mod, temp_path, ANSIBALLZ_PARAMS)\n  File \"/home/alex/.ansible/tmp/ansible-local-30447lh8varvg/ansible-tmp-1587495003.1817515-125465728235717/AnsiballZ_asa_command.py\", line 40, in invoke_module\n    runpy.run_module(mod_name='ansible.modules.network.asa.asa_command', init_globals=None, run_name='__main__', alter_sys=True)\n  File \"/usr/lib64/python3.6/runpy.py\", line 205, in run_module\n    return _run_module_code(code, init_globals, run_name, mod_spec)\n  File \"/usr/lib64/python3.6/runpy.py\", line 96, in _run_module_code\n    mod_name, mod_spec, pkg_name, script_name)\n  File \"/usr/lib64/python3.6/runpy.py\", line 85, in _run_code\n    exec(code, run_globals)\n  File \"/tmp/ansible_asa_command_payload_ud50fwyt/ansible_asa_command_payload.zip/ansible/modules/network/asa/asa_command.py\", line 186, in <module>\n  File \"/tmp/ansible_asa_command_payload_ud50fwyt/ansible_asa_command_payload.zip/ansible/modules/network/asa/asa_command.py\", line 156, in main\n  File \"/tmp/ansible_asa_command_payload_ud50fwyt/ansible_asa_command_payload.zip/ansible/module_utils/network/asa/asa.py\", line 125, in run_commands\n  File \"/tmp/ansible_asa_command_payload_ud50fwyt/ansible_asa_command_payload.zip/ansible/module_utils/connection.py\", line 185, in __rpc__\nansible.module_utils.connection.ConnectionError: y ... Done!\r\nCopying Backup ...\r\n%Error writing tftp://10.1.0.84/fw-inet-wan//FW-WAN.backup.2020-04-22-005004.tar.gz (Timed out attempting to connect)ERROR: Resource temporarily unavailable\r\n Failed!\r\nCleaning up ... Done!\r\nERROR: Backup failed!\r\n\rFW-WAN# \n", "module_stdout": "", "msg": "MODULE FAILURE\nSee stdout/stderr for the exact error", "rc": 1}

PLAY RECAP *********************************************************************
192.168.201.10             : ok=0    changed=0    unreachable=0    failed=1    skipped=0    rescued=0    ignored=0   
192.168.201.18             : ok=0    changed=0    unreachable=0    failed=1    skipped=0    rescued=0    ignored=0   

